<?xml version="1.0"?>
<robot xmlns:xacro="http://www.ros.org/wiki/xacro">

  <!-- Macro for inertial properties of a box -->
  <xacro:macro name="box_inertial" params="mass x y z">
    <inertial>
      <mass value="${mass}"/>
      <inertia ixx="${mass * (y*y + z*z) / 12.0}"
               ixy="0.0" ixz="0.0"
               iyy="${mass * (x*x + z*z) / 12.0}"
               iyz="0.0"
               izz="${mass * (x*x + y*y) / 12.0}"/>
    </inertial>
  </xacro:macro>

  <!-- Macro for inertial properties of a cylinder -->
  <xacro:macro name="cylinder_inertial" params="mass radius length">
    <inertial>
      <mass value="${mass}"/>
      <inertia ixx="${mass * (3*radius*radius + length*length) / 12.0}"
               ixy="0.0" ixz="0.0"
               iyy="${mass * (3*radius*radius + length*length) / 12.0}"
               iyz="0.0"
               izz="${mass * radius*radius / 2.0}"/>
    </inertial>
  </xacro:macro>

  <!-- Macro for inertial properties of a sphere -->
  <xacro:macro name="sphere_inertial" params="mass radius">
    <inertial>
      <mass value="${mass}"/>
      <inertia ixx="${2.0 * mass * radius*radius / 5.0}"
               ixy="0.0" ixz="0.0"
               iyy="${2.0 * mass * radius*radius / 5.0}"
               iyz="0.0"
               izz="${2.0 * mass * radius*radius / 5.0}"/>
    </inertial>
  </xacro:macro>

  <!-- Macro for creating a revolute joint -->
  <xacro:macro name="revolute_joint" params="name parent child xyz rpy axis lower upper velocity effort">
    <joint name="${name}" type="revolute">
      <parent link="${parent}"/>
      <child link="${child}"/>
      <origin xyz="${xyz}" rpy="${rpy}"/>
      <axis xyz="${axis}"/>
      <limit lower="${lower}" upper="${upper}" velocity="${velocity}" effort="${effort}"/>
      <dynamics damping="0.1" friction="0.1"/>
    </joint>
  </xacro:macro>

  <!-- Macro for creating a fixed joint -->
  <xacro:macro name="fixed_joint" params="name parent child xyz rpy">
    <joint name="${name}" type="fixed">
      <parent link="${parent}"/>
      <child link="${child}"/>
      <origin xyz="${xyz}" rpy="${rpy}"/>
    </joint>
  </xacro:macro>

</robot>