<?xml version="1.0" ?>
<!-- =================================================================================== -->
<!-- |    This document was autogenerated by xacro from src/robotArm_4DOF/urdf/robotic_arm.urdf.xacro | -->
<!-- |    EDITING THIS FILE BY HAND IS NOT RECOMMENDED                                 | -->
<!-- =================================================================================== -->
<robot name="robotic_arm_4dof">
  <!-- Material definitions for the robotic arm -->
  <!-- Base material - Dark gray -->
  <material name="base_material">
    <color rgba="0.3 0.3 0.3 1.0"/>
  </material>
  <!-- Link material - Light gray -->
  <material name="link_material">
    <color rgba="0.7 0.7 0.7 1.0"/>
  </material>
  <!-- Joint material - Orange -->
  <material name="joint_material">
    <color rgba="1.0 0.5 0.0 1.0"/>
  </material>
  <!-- End effector material - Blue -->
  <material name="end_effector_material">
    <color rgba="0.0 0.3 0.8 1.0"/>
  </material>
  <!-- Gazebo materials for simulation -->
  <gazebo reference="base_link">
    <material>Gazebo/DarkGrey</material>
  </gazebo>
  <gazebo reference="shoulder_link">
    <material>Gazebo/Grey</material>
  </gazebo>
  <gazebo reference="upper_arm_link">
    <material>Gazebo/Grey</material>
  </gazebo>
  <gazebo reference="forearm_link">
    <material>Gazebo/Grey</material>
  </gazebo>
  <gazebo reference="wrist_link">
    <material>Gazebo/Blue</material>
  </gazebo>
  <!-- World link (fixed reference frame) -->
  <link name="world"/>
  <!-- Base link -->
  <link name="base_link">
    <visual>
      <origin rpy="0 0 0" xyz="0 0 0.025"/>
      <geometry>
        <cylinder length="0.05" radius="0.1"/>
      </geometry>
      <material name="base_material"/>
    </visual>
    <collision>
      <origin rpy="0 0 0" xyz="0 0 0.025"/>
      <geometry>
        <cylinder length="0.05" radius="0.1"/>
      </geometry>
    </collision>
    <inertial>
      <mass value="2.0"/>
      <inertia ixx="0.005416666666666668" ixy="0.0" ixz="0.0" iyy="0.005416666666666668" iyz="0.0" izz="0.010000000000000002"/>
    </inertial>
  </link>
  <!-- Shoulder link -->
  <link name="shoulder_link">
    <visual>
      <origin rpy="0 0 0" xyz="0 0 0.05"/>
      <geometry>
        <cylinder length="0.1" radius="0.05"/>
      </geometry>
      <material name="joint_material"/>
    </visual>
    <collision>
      <origin rpy="0 0 0" xyz="0 0 0.05"/>
      <geometry>
        <cylinder length="0.1" radius="0.05"/>
      </geometry>
    </collision>
    <inertial>
      <mass value="1.0"/>
      <inertia ixx="0.0014583333333333334" ixy="0.0" ixz="0.0" iyy="0.0014583333333333334" iyz="0.0" izz="0.0012500000000000002"/>
    </inertial>
  </link>
  <!-- Upper arm link -->
  <link name="upper_arm_link">
    <visual>
      <origin rpy="0 0 0" xyz="0 0 0.15"/>
      <geometry>
        <cylinder length="0.3" radius="0.03"/>
      </geometry>
      <material name="link_material"/>
    </visual>
    <collision>
      <origin rpy="0 0 0" xyz="0 0 0.15"/>
      <geometry>
        <cylinder length="0.3" radius="0.03"/>
      </geometry>
    </collision>
    <inertial>
      <mass value="1.5"/>
      <inertia ixx="0.011587499999999999" ixy="0.0" ixz="0.0" iyy="0.011587499999999999" iyz="0.0" izz="0.0006749999999999999"/>
    </inertial>
  </link>
  <!-- Forearm link -->
  <link name="forearm_link">
    <visual>
      <origin rpy="0 0 0" xyz="0 0 0.125"/>
      <geometry>
        <cylinder length="0.25" radius="0.025"/>
      </geometry>
      <material name="link_material"/>
    </visual>
    <collision>
      <origin rpy="0 0 0" xyz="0 0 0.125"/>
      <geometry>
        <cylinder length="0.25" radius="0.025"/>
      </geometry>
    </collision>
    <inertial>
      <mass value="1.0"/>
      <inertia ixx="0.005364583333333333" ixy="0.0" ixz="0.0" iyy="0.005364583333333333" iyz="0.0" izz="0.00031250000000000006"/>
    </inertial>
  </link>
  <!-- Wrist link -->
  <link name="wrist_link">
    <visual>
      <origin rpy="0 0 0" xyz="0 0 0.04"/>
      <geometry>
        <sphere radius="0.02"/>
      </geometry>
      <material name="end_effector_material"/>
    </visual>
    <collision>
      <origin rpy="0 0 0" xyz="0 0 0.04"/>
      <geometry>
        <sphere radius="0.02"/>
      </geometry>
    </collision>
    <inertial>
      <mass value="0.5"/>
      <inertia ixx="8e-05" ixy="0.0" ixz="0.0" iyy="8e-05" iyz="0.0" izz="8e-05"/>
    </inertial>
  </link>
  <!-- Joints -->
  <joint name="world_to_base" type="fixed">
    <parent link="world"/>
    <child link="base_link"/>
    <origin rpy="0 0 0" xyz="0 0 0"/>
  </joint>
  <joint name="base_joint" type="revolute">
    <parent link="base_link"/>
    <child link="shoulder_link"/>
    <origin rpy="0 0 0" xyz="0 0 0.05"/>
    <axis xyz="0 0 1"/>
    <limit effort="100.0" lower="-3.14159" upper="3.14159" velocity="2.0"/>
    <dynamics damping="0.1" friction="0.1"/>
  </joint>
  <joint name="shoulder_joint" type="revolute">
    <parent link="shoulder_link"/>
    <child link="upper_arm_link"/>
    <origin rpy="0 0 0" xyz="0 0 0.1"/>
    <axis xyz="0 1 0"/>
    <limit effort="100.0" lower="-1.570795" upper="1.570795" velocity="2.0"/>
    <dynamics damping="0.1" friction="0.1"/>
  </joint>
  <joint name="elbow_joint" type="revolute">
    <parent link="upper_arm_link"/>
    <child link="forearm_link"/>
    <origin rpy="0 0 0" xyz="0 0 0.3"/>
    <axis xyz="0 1 0"/>
    <limit effort="50.0" lower="-3.14159" upper="3.14159" velocity="2.0"/>
    <dynamics damping="0.1" friction="0.1"/>
  </joint>
  <joint name="wrist_joint" type="revolute">
    <parent link="forearm_link"/>
    <child link="wrist_link"/>
    <origin rpy="0 0 0" xyz="0 0 0.25"/>
    <axis xyz="0 1 0"/>
    <limit effort="25.0" lower="-1.570795" upper="1.570795" velocity="2.0"/>
    <dynamics damping="0.1" friction="0.1"/>
  </joint>
</robot>
